<?xml version="1.0" encoding="utf-8"?>
<!-- =================================================================================== -->
<!-- |    This document was autogenerated by xacro from parallel_car.urdf.xacro        | -->
<!-- |    EDITING THIS FILE BY HAND IS NOT RECOMMENDED                                 | -->
<!-- =================================================================================== -->
<robot name="parallel_car">
  <!--gazebo colors-->
  <gazebo reference="car_link">
    <material>Gazebo/Green</material>
  </gazebo>
  <gazebo reference="barX_link">
    <material>Gazebo/Blue</material>
  </gazebo>
  <gazebo reference="barY_link">
    <material>Gazebo/RedGlow</material>
  </gazebo>
  <gazebo reference="barZ_link">
    <material>Gazebo/Yellow</material>
  </gazebo>
  <gazebo reference="wx_link">
    <material>Gazebo/White</material>
  </gazebo>
  <gazebo reference="down_link">
    <material>Gazebo/Grey</material>
  </gazebo>
  <gazebo reference="up_link">
    <material>Gazebo/Orange</material>
  </gazebo>
  <!-- ros_control plugin -->
  <gazebo>
    <plugin filename="libgazebo_ros_control.so" name="gazebo_ros_control">
      <robotNamespace>/parallel_car</robotNamespace>
      <robotSimType>gazebo_ros_control/DefaultRobotHWSim</robotSimType>
    </plugin>
  </gazebo>
  <gazebo>
    <plugin filename="libgazebo_ros_planar_move.so" name="base_controller">
      <commandTopic>cmd_vel</commandTopic>
      <odometryTopic>odom</odometryTopic>
      <odometryFrame>odom</odometryFrame>
      <odometryRate>20.0</odometryRate>
      <robotBaseFrame>car_link</robotBaseFrame>
    </plugin>
  </gazebo>
  <transmission name="car_to_barX_trans">
    <type>transmission_interface/SimpleTransmission</type>
    <joint name="car_to_barX">
      <hardwareInterface>hardware_interface/PositionJointInterface</hardwareInterface>
    </joint>
    <actuator name="car_to_barX_motor">
      <mechanicalReduction>1</mechanicalReduction>
    </actuator>
  </transmission>
  <transmission name="barX_to_barY_trans">
    <type>transmission_interface/SimpleTransmission</type>
    <joint name="barX_to_barY">
      <hardwareInterface>hardware_interface/PositionJointInterface</hardwareInterface>
    </joint>
    <actuator name="barX_to_barY_motor">
      <mechanicalReduction>1</mechanicalReduction>
    </actuator>
  </transmission>
  <transmission name="barY_to_barZ_trans">
    <type>transmission_interface/SimpleTransmission</type>
    <joint name="barY_to_barZ">
      <hardwareInterface>hardware_interface/PositionJointInterface</hardwareInterface>
    </joint>
    <actuator name="barY_to_barZ_motor">
      <mechanicalReduction>1</mechanicalReduction>
    </actuator>
  </transmission>
  <transmission name="barZ_to_littleX_trans">
    <type>transmission_interface/SimpleTransmission</type>
    <joint name="barZ_to_littleX">
      <hardwareInterface>hardware_interface/PositionJointInterface</hardwareInterface>
    </joint>
    <actuator name="barZ_to_littleX_motor">
      <mechanicalReduction>1</mechanicalReduction>
    </actuator>
  </transmission>
  <transmission name="littleX_to_littleY_trans">
    <type>transmission_interface/SimpleTransmission</type>
    <joint name="littleX_to_littleY">
      <hardwareInterface>hardware_interface/PositionJointInterface</hardwareInterface>
    </joint>
    <actuator name="littleX_to_littleY_motor">
      <mechanicalReduction>1</mechanicalReduction>
    </actuator>
  </transmission>
  <transmission name="littleY_to_littleZ_trans">
    <type>transmission_interface/SimpleTransmission</type>
    <joint name="littleY_to_littleZ">
      <hardwareInterface>hardware_interface/PositionJointInterface</hardwareInterface>
    </joint>
    <actuator name="littleY_to_littleZ_motor">
      <mechanicalReduction>1</mechanicalReduction>
    </actuator>
  </transmission>
  <material name="black">
    <color rgba="0.0 0.0 0.0 1.0"/>
  </material>
  <material name="blue">
    <color rgba="0.0 0.0 0.8 1.0"/>
  </material>
  <material name="green">
    <color rgba="0.0 0.8 0.0 1.0"/>
  </material>
  <material name="grey">
    <color rgba="0.2 0.2 0.2 1.0"/>
  </material>
  <material name="orange">
    <color rgba="1.0 0.423529411765 0.0392156862745 1.0"/>
  </material>
  <material name="brown">
    <color rgba="0.870588235294 0.811764705882 0.764705882353 1.0"/>
  </material>
  <material name="red">
    <color rgba="0.8 0.0 0.0 1.0"/>
  </material>
  <material name="white">
    <color rgba="1.0 1.0 1.0 1.0"/>
  </material>
  <material name="yellow">
    <color rgba="1.0 1.0 0.0 1.0"/>
  </material>
  <material name="chocolate">
    <color rgba="0.823529411765 0.411764705882 0.117647058824 1.0"/>
  </material>
  <!-- links -->
  <link name="car_link">
    <!--from origin to top-->
    <visual>
      <geometry>
        <box size="1 0.5 0.36"/>
      </geometry>
      <material name="green"/>
      <origin rpy="0.0 0.0 0.0" xyz="0 0 0.0"/>
    </visual>
    <collision>
      <geometry>
        <box size="1 0.5 0.36"/>
      </geometry>
      <origin rpy="0.0 0.0 0.0" xyz="0 0 0.0"/>
    </collision>
    <inertial>
      <mass value="20.0"/>
      <inertia ixx="20.0" ixy="0.0" ixz="0.0" iyy="20.0" iyz="0.0" izz="20.0"/>
    </inertial>
  </link>
  <link name="barX_link">
    <inertial>
      <origin rpy="0.0 0.0 0.0" xyz="0.0 0.0 0.0"/>
      <mass value="0.01"/>
      <inertia ixx="0.01" ixy="0.0" ixz="0.0" iyy="0.01" iyz="0.0" izz="0.01"/>
    </inertial>
    <visual>
      <origin rpy="0.0 0.0 0.0" xyz="0.0 0.0 0.0"/>
      <geometry>
        <box size="1.0 0.05 0.05"/>
      </geometry>
      <material name="blue"/>
    </visual>
  </link>
  <link name="barY_link">
    <inertial>
      <origin rpy="0.0 0.0 0.0" xyz="0.0 0.0 0.0"/>
      <mass value="0.01"/>
      <inertia ixx="0.01" ixy="0.0" ixz="0.0" iyy="0.01" iyz="0.0" izz="0.01"/>
    </inertial>
    <visual>
      <origin rpy="0.0 0.0 0.0" xyz="0.0 0.0 0.0"/>
      <geometry>
        <box size="0.05 1.0 0.05"/>
      </geometry>
      <material name="red"/>
    </visual>
  </link>
  <link name="barZ_link">
    <inertial>
      <origin rpy="0.0 0.0 0.0" xyz="0.0 0.0 0.0"/>
      <mass value="0.01"/>
      <inertia ixx="0.01" ixy="0.0" ixz="0.0" iyy="0.01" iyz="0.0" izz="0.01"/>
    </inertial>
    <visual>
      <origin rpy="0.0 0.0 0.0" xyz="0.0 0.0 0.0"/>
      <geometry>
        <box size="0.05 0.05 1.0"/>
      </geometry>
      <material name="yellow"/>
    </visual>
  </link>
  <link name="littleX_link">
    <inertial>
      <origin rpy="0.0 0.0 0.0" xyz="0.0 0.0 0.0"/>
      <mass value="0.01"/>
      <inertia ixx="0.01" ixy="0.0" ixz="0.0" iyy="0.01" iyz="0.0" izz="0.01"/>
    </inertial>
    <visual>
      <origin rpy="0.0 0.0 0.0" xyz="0.0 0.0 0.0"/>
      <geometry>
        <box size="0.001 0.001 0.001"/>
      </geometry>
    </visual>
  </link>
  <link name="littleY_link">
    <inertial>
      <origin rpy="0.0 0.0 0.0" xyz="0.0 0.0 0.0"/>
      <mass value="0.01"/>
      <inertia ixx="0.01" ixy="0.0" ixz="0.0" iyy="0.01" iyz="0.0" izz="0.01"/>
    </inertial>
    <visual>
      <origin rpy="0.0 0.0 0.0" xyz="0.0 0.0 0.0"/>
      <geometry>
        <box size="0.001 0.001 0.001"/>
      </geometry>
    </visual>
  </link>
  <link name="littleZ_link">
    <inertial>
      <origin rpy="0.0 0.0 0.0" xyz="0.0 0.0 0.0"/>
      <mass value="0.01"/>
      <inertia ixx="0.01" ixy="0.0" ixz="0.0" iyy="0.01" iyz="0.0" izz="0.01"/>
    </inertial>
    <visual>
      <origin rpy="0.0 0.0 0.0" xyz="0.0 0.0 0.0"/>
      <geometry>
        <box size="0.001 0.001 0.001"/>
      </geometry>
    </visual>
  </link>
  <link name="wx_link">
    <inertial>
      <origin rpy="0.0 0.0 0.0" xyz="0.0 0.0 0.275"/>
      <mass value="5.0"/>
      <inertia ixx="5.0" ixy="0.0" ixz="0.0" iyy="5.0" iyz="0.0" izz="5.0"/>
    </inertial>
    <visual>
      <origin rpy="0.0 3.1415926536 0.0" xyz="0.0 0.0 0.55"/>
      <geometry>
        <mesh filename="package://parallel_car/meshes/MZ.STL"/>
      </geometry>
      <material name="white"/>
    </visual>
    <collision>
      <origin rpy="0.0 0.0 0.0" xyz="0.0 0.0 0.55"/>
      <geometry>
        <mesh filename="package://parallel_car/meshes/MZ.STL"/>
      </geometry>
    </collision>
  </link>
  <!-- up and down links -->
  <link name="down_link">
    <inertial>
      <origin rpy="1.5707963268 0.0 1.5707963268" xyz="0.0 0.0 0.0"/>
      <mass value="0.5"/>
      <inertia ixx="0.5" ixy="0.0" ixz="0.0" iyy="0.5" iyz="0.0" izz="0.5"/>
    </inertial>
    <visual>
      <origin rpy="1.5707963268 0.0 1.5707963268" xyz="0.0 0.0 0.0"/>
      <geometry>
        <mesh filename="package://parallel_car/meshes/platform_down.STL"/>
      </geometry>
      <material name="grey"/>
    </visual>
    <collision>
      <origin rpy="1.5707963268 0.0 1.5707963268" xyz="0.0 0.0 0.0"/>
      <geometry>
        <mesh filename="package://parallel_car/meshes/platform_down.STL"/>
      </geometry>
    </collision>
  </link>
  <link name="up_link">
    <inertial>
      <origin rpy="-1.5707963268 0.0 -0.5235987756" xyz="0.0 0.0 0.0"/>
      <mass value="0.3"/>
      <inertia ixx="0.3" ixy="0.0" ixz="0.0" iyy="0.3" iyz="0.0" izz="0.3"/>
    </inertial>
    <visual>
      <origin rpy="-1.5707963268 0.0 -0.5235987756" xyz="0.0 0.0 0.0"/>
      <geometry>
        <mesh filename="package://parallel_car/meshes/platform_up.STL"/>
      </geometry>
      <material name="orange"/>
    </visual>
    <collision>
      <origin rpy="-1.5707963268 0.0 -0.5235987756" xyz="0.0 0.0 0.0"/>
      <geometry>
        <mesh filename="package://parallel_car/meshes/platform_up.STL"/>
      </geometry>
    </collision>
  </link>
  <!-- joints -->
  <joint name="car_to_barX" type="prismatic">
    <origin rpy="0.0 0.0 0.0" xyz="0.0 0.0 0.18"/>
    <parent link="car_link"/>
    <child link="barX_link"/>
    <axis xyz="1.0 0.0 0.0"/>
    <limit effort="5.0" lower="-0.5" upper="0.5" velocity="0.5"/>
  </joint>
  <joint name="barX_to_barY" type="prismatic">
    <origin rpy="0.0 0.0 0.0" xyz="0.0 0.0 0.05"/>
    <parent link="barX_link"/>
    <child link="barY_link"/>
    <axis xyz="0.0 1.0 0.0"/>
    <limit effort="5.0" lower="-0.5" upper="0.5" velocity="0.5"/>
  </joint>
  <joint name="barY_to_barZ" type="prismatic">
    <origin rpy="0.0 0.0 0.0" xyz="0.0 0.0 0.525"/>
    <parent link="barY_link"/>
    <child link="barZ_link"/>
    <axis xyz="0.0 0.0 1.0"/>
    <limit effort="5.0" lower="-0.5" upper="0.5" velocity="0.5"/>
  </joint>
  <joint name="barZ_to_littleX" type="revolute">
    <origin rpy="0.0 0.0 0.0" xyz="0.0 0.0 0.5"/>
    <parent link="barZ_link"/>
    <child link="littleX_link"/>
    <axis xyz="1.0 0.0 0.0"/>
    <limit effort="5.0" lower="-1.5707963268" upper="1.5707963268" velocity="0.5"/>
  </joint>
  <joint name="littleX_to_littleY" type="revolute">
    <origin rpy="0.0 0.0 0.0" xyz="0.0 0.0 0.0"/>
    <parent link="littleX_link"/>
    <child link="littleY_link"/>
    <axis xyz="0.0 1.0 0.0"/>
    <limit effort="5.0" lower="-1.5707963268" upper="1.5707963268" velocity="0.5"/>
  </joint>
  <joint name="littleY_to_littleZ" type="revolute">
    <origin rpy="0.0 0.0 0.0" xyz="0.0 0.0 0.0"/>
    <parent link="littleY_link"/>
    <child link="littleZ_link"/>
    <axis xyz="0.0 0.0 1.0"/>
    <limit effort="5.0" lower="-1.5707963268" upper="1.5707963268" velocity="0.5"/>
  </joint>
  <joint name="littleZ_to_wx" type="fixed">
    <origin rpy="0.0 0.0 0.0" xyz="0.0 0.0 0.0"/>
    <parent link="littleZ_link"/>
    <child link="wx_link"/>
  </joint>
  <!-- up and down joints -->
  <joint name="car_to_down" type="fixed">
    <origin rpy="0.0 0.0 0.0" xyz="0.0 0.0 0.18"/>
    <parent link="car_link"/>
    <child link="down_link"/>
  </joint>
  <joint name="littleY_to_up" type="fixed">
    <origin rpy="0.0 0.0 0.0" xyz="0.0 0.0 0.0"/>
    <parent link="littleY_link"/>
    <child link="up_link"/>
  </joint>
  <!-- beta in degrees, convertion is needed, and is just the degrees needed to rotate-->
  <!--down_link, positive x axis-->
  <joint name="up_to_down_1_medium" type="fixed">
    <origin rpy="0.0 0.0 0.174532925199" xyz="0.0 0.0 0.0"/>
    <parent link="down_link"/>
    <child link="down_1_medium"/>
  </joint>
  <link name="down_1_medium">
    <inertial>
      <origin rpy="0.0 0.0 0.0" xyz="0.0 0.0 0.0"/>
      <mass value="0.01"/>
      <inertia ixx="0.01" ixy="0.0" ixz="0.0" iyy="0.01" iyz="0.0" izz="0.01"/>
    </inertial>
    <visual>
      <origin rpy="0.0 0.0 0.0" xyz="0.0 0.0 0.0"/>
      <geometry>
        <box size="0.001 0.001 0.001"/>
      </geometry>
    </visual>
  </link>
  <joint name="medium_to_down_1" type="fixed">
    <origin rpy="0.0 0.0 0.0" xyz="0.2 0.0 0.075"/>
    <parent link="down_1_medium"/>
    <child link="down_1"/>
  </joint>
  <link name="down_1">
    <inertial>
      <origin rpy="0.0 0.0 0.0" xyz="0.0 0.0 0.0"/>
      <mass value="0.01"/>
      <inertia ixx="0.01" ixy="0.0" ixz="0.0" iyy="0.01" iyz="0.0" izz="0.01"/>
    </inertial>
    <visual>
      <origin rpy="0.0 0.0 0.0" xyz="0.0 0.0 0.0"/>
      <geometry>
        <box size="0.001 0.001 0.001"/>
      </geometry>
    </visual>
  </link>
  <!-- beta in degrees, convertion is needed, and is just the degrees needed to rotate-->
  <!--down_link, positive x axis-->
  <joint name="up_to_down_2_medium" type="fixed">
    <origin rpy="0.0 0.0 1.91986217719" xyz="0.0 0.0 0.0"/>
    <parent link="down_link"/>
    <child link="down_2_medium"/>
  </joint>
  <link name="down_2_medium">
    <inertial>
      <origin rpy="0.0 0.0 0.0" xyz="0.0 0.0 0.0"/>
      <mass value="0.01"/>
      <inertia ixx="0.01" ixy="0.0" ixz="0.0" iyy="0.01" iyz="0.0" izz="0.01"/>
    </inertial>
    <visual>
      <origin rpy="0.0 0.0 0.0" xyz="0.0 0.0 0.0"/>
      <geometry>
        <box size="0.001 0.001 0.001"/>
      </geometry>
    </visual>
  </link>
  <joint name="medium_to_down_2" type="fixed">
    <origin rpy="0.0 0.0 0.0" xyz="0.2 0.0 0.075"/>
    <parent link="down_2_medium"/>
    <child link="down_2"/>
  </joint>
  <link name="down_2">
    <inertial>
      <origin rpy="0.0 0.0 0.0" xyz="0.0 0.0 0.0"/>
      <mass value="0.01"/>
      <inertia ixx="0.01" ixy="0.0" ixz="0.0" iyy="0.01" iyz="0.0" izz="0.01"/>
    </inertial>
    <visual>
      <origin rpy="0.0 0.0 0.0" xyz="0.0 0.0 0.0"/>
      <geometry>
        <box size="0.001 0.001 0.001"/>
      </geometry>
    </visual>
  </link>
  <!-- beta in degrees, convertion is needed, and is just the degrees needed to rotate-->
  <!--down_link, positive x axis-->
  <joint name="up_to_down_3_medium" type="fixed">
    <origin rpy="0.0 0.0 2.26892802759" xyz="0.0 0.0 0.0"/>
    <parent link="down_link"/>
    <child link="down_3_medium"/>
  </joint>
  <link name="down_3_medium">
    <inertial>
      <origin rpy="0.0 0.0 0.0" xyz="0.0 0.0 0.0"/>
      <mass value="0.01"/>
      <inertia ixx="0.01" ixy="0.0" ixz="0.0" iyy="0.01" iyz="0.0" izz="0.01"/>
    </inertial>
    <visual>
      <origin rpy="0.0 0.0 0.0" xyz="0.0 0.0 0.0"/>
      <geometry>
        <box size="0.001 0.001 0.001"/>
      </geometry>
    </visual>
  </link>
  <joint name="medium_to_down_3" type="fixed">
    <origin rpy="0.0 0.0 0.0" xyz="0.2 0.0 0.075"/>
    <parent link="down_3_medium"/>
    <child link="down_3"/>
  </joint>
  <link name="down_3">
    <inertial>
      <origin rpy="0.0 0.0 0.0" xyz="0.0 0.0 0.0"/>
      <mass value="0.01"/>
      <inertia ixx="0.01" ixy="0.0" ixz="0.0" iyy="0.01" iyz="0.0" izz="0.01"/>
    </inertial>
    <visual>
      <origin rpy="0.0 0.0 0.0" xyz="0.0 0.0 0.0"/>
      <geometry>
        <box size="0.001 0.001 0.001"/>
      </geometry>
    </visual>
  </link>
  <!-- beta in degrees, convertion is needed, and is just the degrees needed to rotate-->
  <!--down_link, positive x axis-->
  <joint name="up_to_down_4_medium" type="fixed">
    <origin rpy="0.0 0.0 4.01425727959" xyz="0.0 0.0 0.0"/>
    <parent link="down_link"/>
    <child link="down_4_medium"/>
  </joint>
  <link name="down_4_medium">
    <inertial>
      <origin rpy="0.0 0.0 0.0" xyz="0.0 0.0 0.0"/>
      <mass value="0.01"/>
      <inertia ixx="0.01" ixy="0.0" ixz="0.0" iyy="0.01" iyz="0.0" izz="0.01"/>
    </inertial>
    <visual>
      <origin rpy="0.0 0.0 0.0" xyz="0.0 0.0 0.0"/>
      <geometry>
        <box size="0.001 0.001 0.001"/>
      </geometry>
    </visual>
  </link>
  <joint name="medium_to_down_4" type="fixed">
    <origin rpy="0.0 0.0 0.0" xyz="0.2 0.0 0.075"/>
    <parent link="down_4_medium"/>
    <child link="down_4"/>
  </joint>
  <link name="down_4">
    <inertial>
      <origin rpy="0.0 0.0 0.0" xyz="0.0 0.0 0.0"/>
      <mass value="0.01"/>
      <inertia ixx="0.01" ixy="0.0" ixz="0.0" iyy="0.01" iyz="0.0" izz="0.01"/>
    </inertial>
    <visual>
      <origin rpy="0.0 0.0 0.0" xyz="0.0 0.0 0.0"/>
      <geometry>
        <box size="0.001 0.001 0.001"/>
      </geometry>
    </visual>
  </link>
  <!-- beta in degrees, convertion is needed, and is just the degrees needed to rotate-->
  <!--down_link, positive x axis-->
  <joint name="up_to_down_5_medium" type="fixed">
    <origin rpy="0.0 0.0 4.36332312999" xyz="0.0 0.0 0.0"/>
    <parent link="down_link"/>
    <child link="down_5_medium"/>
  </joint>
  <link name="down_5_medium">
    <inertial>
      <origin rpy="0.0 0.0 0.0" xyz="0.0 0.0 0.0"/>
      <mass value="0.01"/>
      <inertia ixx="0.01" ixy="0.0" ixz="0.0" iyy="0.01" iyz="0.0" izz="0.01"/>
    </inertial>
    <visual>
      <origin rpy="0.0 0.0 0.0" xyz="0.0 0.0 0.0"/>
      <geometry>
        <box size="0.001 0.001 0.001"/>
      </geometry>
    </visual>
  </link>
  <joint name="medium_to_down_5" type="fixed">
    <origin rpy="0.0 0.0 0.0" xyz="0.2 0.0 0.075"/>
    <parent link="down_5_medium"/>
    <child link="down_5"/>
  </joint>
  <link name="down_5">
    <inertial>
      <origin rpy="0.0 0.0 0.0" xyz="0.0 0.0 0.0"/>
      <mass value="0.01"/>
      <inertia ixx="0.01" ixy="0.0" ixz="0.0" iyy="0.01" iyz="0.0" izz="0.01"/>
    </inertial>
    <visual>
      <origin rpy="0.0 0.0 0.0" xyz="0.0 0.0 0.0"/>
      <geometry>
        <box size="0.001 0.001 0.001"/>
      </geometry>
    </visual>
  </link>
  <!-- beta in degrees, convertion is needed, and is just the degrees needed to rotate-->
  <!--down_link, positive x axis-->
  <joint name="up_to_down_6_medium" type="fixed">
    <origin rpy="0.0 0.0 6.10865238198" xyz="0.0 0.0 0.0"/>
    <parent link="down_link"/>
    <child link="down_6_medium"/>
  </joint>
  <link name="down_6_medium">
    <inertial>
      <origin rpy="0.0 0.0 0.0" xyz="0.0 0.0 0.0"/>
      <mass value="0.01"/>
      <inertia ixx="0.01" ixy="0.0" ixz="0.0" iyy="0.01" iyz="0.0" izz="0.01"/>
    </inertial>
    <visual>
      <origin rpy="0.0 0.0 0.0" xyz="0.0 0.0 0.0"/>
      <geometry>
        <box size="0.001 0.001 0.001"/>
      </geometry>
    </visual>
  </link>
  <joint name="medium_to_down_6" type="fixed">
    <origin rpy="0.0 0.0 0.0" xyz="0.2 0.0 0.075"/>
    <parent link="down_6_medium"/>
    <child link="down_6"/>
  </joint>
  <link name="down_6">
    <inertial>
      <origin rpy="0.0 0.0 0.0" xyz="0.0 0.0 0.0"/>
      <mass value="0.01"/>
      <inertia ixx="0.01" ixy="0.0" ixz="0.0" iyy="0.01" iyz="0.0" izz="0.01"/>
    </inertial>
    <visual>
      <origin rpy="0.0 0.0 0.0" xyz="0.0 0.0 0.0"/>
      <geometry>
        <box size="0.001 0.001 0.001"/>
      </geometry>
    </visual>
  </link>
  <!-- beta in degrees, convertion is needed, and is just the degrees needed to rotate-->
  <!--up_link, positive x axis-->
  <joint name="up_to_up_1_medium" type="fixed">
    <origin rpy="0.0 0.0 0.872664625997" xyz="0.0 0.0 0.0"/>
    <parent link="up_link"/>
    <child link="up_1_medium"/>
  </joint>
  <link name="up_1_medium">
    <inertial>
      <origin rpy="0.0 0.0 0.0" xyz="0.0 0.0 0.0"/>
      <mass value="0.01"/>
      <inertia ixx="0.01" ixy="0.0" ixz="0.0" iyy="0.01" iyz="0.0" izz="0.01"/>
    </inertial>
    <visual>
      <origin rpy="0.0 0.0 0.0" xyz="0.0 0.0 0.0"/>
      <geometry>
        <box size="0.001 0.001 0.001"/>
      </geometry>
    </visual>
  </link>
  <joint name="medium_to_up_1" type="fixed">
    <origin rpy="0.0 0.0 0.0" xyz="0.1 0.0 -0.05"/>
    <parent link="up_1_medium"/>
    <child link="up_1"/>
  </joint>
  <link name="up_1">
    <inertial>
      <origin rpy="0.0 0.0 0.0" xyz="0.0 0.0 0.0"/>
      <mass value="0.01"/>
      <inertia ixx="0.01" ixy="0.0" ixz="0.0" iyy="0.01" iyz="0.0" izz="0.01"/>
    </inertial>
    <visual>
      <origin rpy="0.0 0.0 0.0" xyz="0.0 0.0 0.0"/>
      <geometry>
        <box size="0.001 0.001 0.001"/>
      </geometry>
    </visual>
  </link>
  <!-- beta in degrees, convertion is needed, and is just the degrees needed to rotate-->
  <!--up_link, positive x axis-->
  <joint name="up_to_up_2_medium" type="fixed">
    <origin rpy="0.0 0.0 1.2217304764" xyz="0.0 0.0 0.0"/>
    <parent link="up_link"/>
    <child link="up_2_medium"/>
  </joint>
  <link name="up_2_medium">
    <inertial>
      <origin rpy="0.0 0.0 0.0" xyz="0.0 0.0 0.0"/>
      <mass value="0.01"/>
      <inertia ixx="0.01" ixy="0.0" ixz="0.0" iyy="0.01" iyz="0.0" izz="0.01"/>
    </inertial>
    <visual>
      <origin rpy="0.0 0.0 0.0" xyz="0.0 0.0 0.0"/>
      <geometry>
        <box size="0.001 0.001 0.001"/>
      </geometry>
    </visual>
  </link>
  <joint name="medium_to_up_2" type="fixed">
    <origin rpy="0.0 0.0 0.0" xyz="0.1 0.0 -0.05"/>
    <parent link="up_2_medium"/>
    <child link="up_2"/>
  </joint>
  <link name="up_2">
    <inertial>
      <origin rpy="0.0 0.0 0.0" xyz="0.0 0.0 0.0"/>
      <mass value="0.01"/>
      <inertia ixx="0.01" ixy="0.0" ixz="0.0" iyy="0.01" iyz="0.0" izz="0.01"/>
    </inertial>
    <visual>
      <origin rpy="0.0 0.0 0.0" xyz="0.0 0.0 0.0"/>
      <geometry>
        <box size="0.001 0.001 0.001"/>
      </geometry>
    </visual>
  </link>
  <!-- beta in degrees, convertion is needed, and is just the degrees needed to rotate-->
  <!--up_link, positive x axis-->
  <joint name="up_to_up_3_medium" type="fixed">
    <origin rpy="0.0 0.0 2.96705972839" xyz="0.0 0.0 0.0"/>
    <parent link="up_link"/>
    <child link="up_3_medium"/>
  </joint>
  <link name="up_3_medium">
    <inertial>
      <origin rpy="0.0 0.0 0.0" xyz="0.0 0.0 0.0"/>
      <mass value="0.01"/>
      <inertia ixx="0.01" ixy="0.0" ixz="0.0" iyy="0.01" iyz="0.0" izz="0.01"/>
    </inertial>
    <visual>
      <origin rpy="0.0 0.0 0.0" xyz="0.0 0.0 0.0"/>
      <geometry>
        <box size="0.001 0.001 0.001"/>
      </geometry>
    </visual>
  </link>
  <joint name="medium_to_up_3" type="fixed">
    <origin rpy="0.0 0.0 0.0" xyz="0.1 0.0 -0.05"/>
    <parent link="up_3_medium"/>
    <child link="up_3"/>
  </joint>
  <link name="up_3">
    <inertial>
      <origin rpy="0.0 0.0 0.0" xyz="0.0 0.0 0.0"/>
      <mass value="0.01"/>
      <inertia ixx="0.01" ixy="0.0" ixz="0.0" iyy="0.01" iyz="0.0" izz="0.01"/>
    </inertial>
    <visual>
      <origin rpy="0.0 0.0 0.0" xyz="0.0 0.0 0.0"/>
      <geometry>
        <box size="0.001 0.001 0.001"/>
      </geometry>
    </visual>
  </link>
  <!-- beta in degrees, convertion is needed, and is just the degrees needed to rotate-->
  <!--up_link, positive x axis-->
  <joint name="up_to_up_4_medium" type="fixed">
    <origin rpy="0.0 0.0 3.31612557879" xyz="0.0 0.0 0.0"/>
    <parent link="up_link"/>
    <child link="up_4_medium"/>
  </joint>
  <link name="up_4_medium">
    <inertial>
      <origin rpy="0.0 0.0 0.0" xyz="0.0 0.0 0.0"/>
      <mass value="0.01"/>
      <inertia ixx="0.01" ixy="0.0" ixz="0.0" iyy="0.01" iyz="0.0" izz="0.01"/>
    </inertial>
    <visual>
      <origin rpy="0.0 0.0 0.0" xyz="0.0 0.0 0.0"/>
      <geometry>
        <box size="0.001 0.001 0.001"/>
      </geometry>
    </visual>
  </link>
  <joint name="medium_to_up_4" type="fixed">
    <origin rpy="0.0 0.0 0.0" xyz="0.1 0.0 -0.05"/>
    <parent link="up_4_medium"/>
    <child link="up_4"/>
  </joint>
  <link name="up_4">
    <inertial>
      <origin rpy="0.0 0.0 0.0" xyz="0.0 0.0 0.0"/>
      <mass value="0.01"/>
      <inertia ixx="0.01" ixy="0.0" ixz="0.0" iyy="0.01" iyz="0.0" izz="0.01"/>
    </inertial>
    <visual>
      <origin rpy="0.0 0.0 0.0" xyz="0.0 0.0 0.0"/>
      <geometry>
        <box size="0.001 0.001 0.001"/>
      </geometry>
    </visual>
  </link>
  <!-- beta in degrees, convertion is needed, and is just the degrees needed to rotate-->
  <!--up_link, positive x axis-->
  <joint name="up_to_up_5_medium" type="fixed">
    <origin rpy="0.0 0.0 5.06145483078" xyz="0.0 0.0 0.0"/>
    <parent link="up_link"/>
    <child link="up_5_medium"/>
  </joint>
  <link name="up_5_medium">
    <inertial>
      <origin rpy="0.0 0.0 0.0" xyz="0.0 0.0 0.0"/>
      <mass value="0.01"/>
      <inertia ixx="0.01" ixy="0.0" ixz="0.0" iyy="0.01" iyz="0.0" izz="0.01"/>
    </inertial>
    <visual>
      <origin rpy="0.0 0.0 0.0" xyz="0.0 0.0 0.0"/>
      <geometry>
        <box size="0.001 0.001 0.001"/>
      </geometry>
    </visual>
  </link>
  <joint name="medium_to_up_5" type="fixed">
    <origin rpy="0.0 0.0 0.0" xyz="0.1 0.0 -0.05"/>
    <parent link="up_5_medium"/>
    <child link="up_5"/>
  </joint>
  <link name="up_5">
    <inertial>
      <origin rpy="0.0 0.0 0.0" xyz="0.0 0.0 0.0"/>
      <mass value="0.01"/>
      <inertia ixx="0.01" ixy="0.0" ixz="0.0" iyy="0.01" iyz="0.0" izz="0.01"/>
    </inertial>
    <visual>
      <origin rpy="0.0 0.0 0.0" xyz="0.0 0.0 0.0"/>
      <geometry>
        <box size="0.001 0.001 0.001"/>
      </geometry>
    </visual>
  </link>
  <!-- beta in degrees, convertion is needed, and is just the degrees needed to rotate-->
  <!--up_link, positive x axis-->
  <joint name="up_to_up_6_medium" type="fixed">
    <origin rpy="0.0 0.0 5.41052068118" xyz="0.0 0.0 0.0"/>
    <parent link="up_link"/>
    <child link="up_6_medium"/>
  </joint>
  <link name="up_6_medium">
    <inertial>
      <origin rpy="0.0 0.0 0.0" xyz="0.0 0.0 0.0"/>
      <mass value="0.01"/>
      <inertia ixx="0.01" ixy="0.0" ixz="0.0" iyy="0.01" iyz="0.0" izz="0.01"/>
    </inertial>
    <visual>
      <origin rpy="0.0 0.0 0.0" xyz="0.0 0.0 0.0"/>
      <geometry>
        <box size="0.001 0.001 0.001"/>
      </geometry>
    </visual>
  </link>
  <joint name="medium_to_up_6" type="fixed">
    <origin rpy="0.0 0.0 0.0" xyz="0.1 0.0 -0.05"/>
    <parent link="up_6_medium"/>
    <child link="up_6"/>
  </joint>
  <link name="up_6">
    <inertial>
      <origin rpy="0.0 0.0 0.0" xyz="0.0 0.0 0.0"/>
      <mass value="0.01"/>
      <inertia ixx="0.01" ixy="0.0" ixz="0.0" iyy="0.01" iyz="0.0" izz="0.01"/>
    </inertial>
    <visual>
      <origin rpy="0.0 0.0 0.0" xyz="0.0 0.0 0.0"/>
      <geometry>
        <box size="0.001 0.001 0.001"/>
      </geometry>
    </visual>
  </link>
</robot>
