<?xml version="1.0" encoding="utf-8"?>
<!-- =================================================================================== -->
<!-- |    This document was autogenerated by xacro from parallel_car.urdf.xacro        | -->
<!-- |    EDITING THIS FILE BY HAND IS NOT RECOMMENDED                                 | -->
<!-- =================================================================================== -->
<robot name="parallel_car">
  <!--gazebo colors-->
  <gazebo reference="car_link">
    <material>Gazebo/Green</material>
  </gazebo>
  <gazebo reference="barX_link">
    <material>Gazebo/Blue</material>
  </gazebo>
  <gazebo reference="barY_link">
    <material>Gazebo/RedGlow</material>
  </gazebo>
  <gazebo reference="barZ_link">
    <material>Gazebo/Yellow</material>
  </gazebo>
  <gazebo reference="wx_link">
    <material>Gazebo/White</material>
  </gazebo>
  <!-- ros_control plugin -->
  <gazebo>
    <plugin filename="libgazebo_ros_control.so" name="gazebo_ros_control">
      <robotNamespace>/</robotNamespace>
      <robotSimType>gazebo_ros_control/DefaultRobotHWSim</robotSimType>
    </plugin>
  </gazebo>
  <gazebo>
    <plugin filename="libgazebo_ros_planar_move.so" name="base_controller">
      <commandTopic>cmd_vel</commandTopic>
      <odometryTopic>odom</odometryTopic>
      <odometryFrame>odom</odometryFrame>
      <odometryRate>20.0</odometryRate>
      <robotBaseFrame>car_link</robotBaseFrame>
    </plugin>
  </gazebo>
  <transmission name="car_to_barX_trans">
    <type>transmission_interface/SimpleTransmission</type>
    <joint name="car_to_barX">
      <hardwareInterface>hardware_interface/PositionJointInterface</hardwareInterface>
    </joint>
    <actuator name="car_to_barX_motor">
      <mechanicalReduction>1</mechanicalReduction>
    </actuator>
  </transmission>
  <transmission name="barX_to_barY_trans">
    <type>transmission_interface/SimpleTransmission</type>
    <joint name="barX_to_barY">
      <hardwareInterface>hardware_interface/PositionJointInterface</hardwareInterface>
    </joint>
    <actuator name="barX_to_barY_motor">
      <mechanicalReduction>1</mechanicalReduction>
    </actuator>
  </transmission>
  <transmission name="barY_to_barZ_trans">
    <type>transmission_interface/SimpleTransmission</type>
    <joint name="barY_to_barZ">
      <hardwareInterface>hardware_interface/PositionJointInterface</hardwareInterface>
    </joint>
    <actuator name="barY_to_barZ_motor">
      <mechanicalReduction>1</mechanicalReduction>
    </actuator>
  </transmission>
  <transmission name="barZ_to_littleX_trans">
    <type>transmission_interface/SimpleTransmission</type>
    <joint name="barZ_to_littleX">
      <hardwareInterface>hardware_interface/PositionJointInterface</hardwareInterface>
    </joint>
    <actuator name="barZ_to_littleX_motor">
      <mechanicalReduction>1</mechanicalReduction>
    </actuator>
  </transmission>
  <transmission name="littleX_to_littleY_trans">
    <type>transmission_interface/SimpleTransmission</type>
    <joint name="littleX_to_littleY">
      <hardwareInterface>hardware_interface/PositionJointInterface</hardwareInterface>
    </joint>
    <actuator name="littleX_to_littleY_motor">
      <mechanicalReduction>1</mechanicalReduction>
    </actuator>
  </transmission>
  <transmission name="littleY_to_littleZ_trans">
    <type>transmission_interface/SimpleTransmission</type>
    <joint name="littleY_to_littleZ">
      <hardwareInterface>hardware_interface/PositionJointInterface</hardwareInterface>
    </joint>
    <actuator name="littleY_to_littleZ_motor">
      <mechanicalReduction>1</mechanicalReduction>
    </actuator>
  </transmission>
  <!-- links -->
  <link name="car_link">
    <!--from origin to top-->
    <visual>
      <geometry>
        <mesh filename="package://parallel_car/meshes/car.STL"/>
      </geometry>
      <material name="ForestGreen">
        <color rgba="0.15 0.5 0.15 0.5"/>
      </material>
      <origin rpy="1.5707963268 0 1.5707963268" xyz="0 0 0.23"/>
    </visual>
    <collision>
      <geometry>
        <mesh filename="package://parallel_car/meshes/car.STL"/>
      </geometry>
      <origin rpy="1.5707963268 0 1.5707963268" xyz="0 0 0.23"/>
    </collision>
    <inertial>
      <mass value="20.0"/>
      <inertia ixx="20.0" ixy="0.0" ixz="0.0" iyy="20.0" iyz="0.0" izz="20.0"/>
    </inertial>
  </link>
  <link name="barX_link">
    <inertial>
      <origin rpy="0.0 0.0 0.0" xyz="0.0 0.0 0.0"/>
      <mass value="0.01"/>
      <inertia ixx="0.01" ixy="0.0" ixz="0.0" iyy="0.01" iyz="0.0" izz="0.01"/>
    </inertial>
    <visual>
      <origin rpy="0.0 0.0 0.0" xyz="0.0 0.0 0.0"/>
      <geometry>
        <box size="1.0 0.05 0.05"/>
      </geometry>
      <material name="Blue">
        <color rgba="0.0 0.0 1.0 0.5"/>
      </material>
    </visual>
  </link>
  <link name="barY_link">
    <inertial>
      <origin rpy="0.0 0.0 0.0" xyz="0.0 0.0 0.0"/>
      <mass value="0.01"/>
      <inertia ixx="0.01" ixy="0.0" ixz="0.0" iyy="0.01" iyz="0.0" izz="0.01"/>
    </inertial>
    <visual>
      <origin rpy="0.0 0.0 0.0" xyz="0.0 0.0 0.0"/>
      <geometry>
        <box size="0.05 1.0 0.05"/>
      </geometry>
      <material name="Crimson">
        <color rgba="0.8 0.1 0.25 0.5"/>
      </material>
    </visual>
  </link>
  <link name="barZ_link">
    <inertial>
      <origin rpy="0.0 0.0 0.0" xyz="0.0 0.0 0.0"/>
      <mass value="0.01"/>
      <inertia ixx="0.01" ixy="0.0" ixz="0.0" iyy="0.01" iyz="0.0" izz="0.01"/>
    </inertial>
    <visual>
      <origin rpy="0.0 0.0 0.0" xyz="0.0 0.0 0.0"/>
      <geometry>
        <box size="0.05 0.05 1.0"/>
      </geometry>
      <material name="Yellow">
        <color rgba="1.0 1.0 0.0 0.5"/>
      </material>
    </visual>
  </link>
  <link name="littleX_link">
    <inertial>
      <origin rpy="0.0 0.0 0.0" xyz="0.0 0.0 0.0"/>
      <mass value="0.01"/>
      <inertia ixx="0.01" ixy="0.0" ixz="0.0" iyy="0.01" iyz="0.0" izz="0.01"/>
    </inertial>
    <visual>
      <origin rpy="0.0 0.0 0.0" xyz="0.0 0.0 0.0"/>
      <geometry>
        <box size="0.001 0.001 0.001"/>
      </geometry>
      <material name="Chocolate">
        <color rgba="0.8 0.5 0.125 0.5"/>
      </material>
    </visual>
  </link>
  <link name="littleY_link">
    <inertial>
      <origin rpy="0.0 0.0 0.0" xyz="0.0 0.0 0.0"/>
      <mass value="0.01"/>
      <inertia ixx="0.01" ixy="0.0" ixz="0.0" iyy="0.01" iyz="0.0" izz="0.01"/>
    </inertial>
    <visual>
      <origin rpy="0.0 0.0 0.0" xyz="0.0 0.0 0.0"/>
      <geometry>
        <box size="0.001 0.001 0.001"/>
      </geometry>
      <material name="DarkGreen">
        <color rgba="0.0 0.5 0.0 0.5"/>
      </material>
    </visual>
  </link>
  <link name="littleZ_link">
    <inertial>
      <origin rpy="0.0 0.0 0.0" xyz="0.0 0.0 0.0"/>
      <mass value="0.01"/>
      <inertia ixx="0.01" ixy="0.0" ixz="0.0" iyy="0.01" iyz="0.0" izz="0.01"/>
    </inertial>
    <visual>
      <origin rpy="0.0 0.0 0.0" xyz="0.0 0.0 0.0"/>
      <geometry>
        <box size="0.001 0.001 0.001"/>
      </geometry>
      <material name="Red">
        <color rgba="1.0 0.0 0.0 0.5"/>
      </material>
    </visual>
  </link>
  <link name="wx_link">
    <inertial>
      <origin rpy="0.0 0.0 0.0" xyz="0.0 0.0 0.275"/>
      <mass value="5.0"/>
      <inertia ixx="5.0" ixy="0.0" ixz="0.0" iyy="5.0" iyz="0.0" izz="5.0"/>
    </inertial>
    <visual>
      <origin rpy="0.0 3.1415926536 0.0" xyz="0.0 0.0 0.55"/>
      <geometry>
        <mesh filename="package://parallel_car/meshes/MZ.STL"/>
      </geometry>
      <material name="White">
        <color rgba="1.0 1.0 1.0 0.5"/>
      </material>
    </visual>
    <collision>
      <origin rpy="0.0 0.0 0.0" xyz="0.0 0.0 0.55"/>
      <geometry>
        <mesh filename="package://parallel_car/meshes/MZ.STL"/>
      </geometry>
    </collision>
  </link>
  <!-- joints -->
  <joint name="car_to_barX" type="prismatic">
    <origin rpy="0.0 0.0 0.0" xyz="0.0 0.0 0.18"/>
    <parent link="car_link"/>
    <child link="barX_link"/>
    <axis xyz="1.0 0.0 0.0"/>
    <limit effort="5.0" lower="-0.5" upper="0.5" velocity="0.5"/>
  </joint>
  <joint name="barX_to_barY" type="prismatic">
    <origin rpy="0.0 0.0 0.0" xyz="0.0 0.0 0.05"/>
    <parent link="barX_link"/>
    <child link="barY_link"/>
    <axis xyz="0.0 1.0 0.0"/>
    <limit effort="5.0" lower="-0.5" upper="0.5" velocity="0.5"/>
  </joint>
  <joint name="barY_to_barZ" type="prismatic">
    <origin rpy="0.0 0.0 0.0" xyz="0.0 0.0 0.525"/>
    <parent link="barY_link"/>
    <child link="barZ_link"/>
    <axis xyz="0.0 0.0 1.0"/>
    <limit effort="5.0" lower="-0.5" upper="0.5" velocity="0.5"/>
  </joint>
  <joint name="barZ_to_littleX" type="revolute">
    <origin rpy="0.0 0.0 0.0" xyz="0.0 0.0 0.5"/>
    <parent link="barZ_link"/>
    <child link="littleX_link"/>
    <axis xyz="1.0 0.0 0.0"/>
    <limit effort="5.0" lower="-1.5707963268" upper="1.5707963268" velocity="0.5"/>
  </joint>
  <joint name="littleX_to_littleY" type="revolute">
    <origin rpy="0.0 0.0 0.0" xyz="0.0 0.0 0.0"/>
    <parent link="littleX_link"/>
    <child link="littleY_link"/>
    <axis xyz="0.0 1.0 0.0"/>
    <limit effort="5.0" lower="-1.5707963268" upper="1.5707963268" velocity="0.5"/>
  </joint>
  <joint name="littleY_to_littleZ" type="revolute">
    <origin rpy="0.0 0.0 0.0" xyz="0.0 0.0 0.0"/>
    <parent link="littleY_link"/>
    <child link="littleZ_link"/>
    <axis xyz="0.0 0.0 1.0"/>
    <limit effort="5.0" lower="-1.5707963268" upper="1.5707963268" velocity="0.5"/>
  </joint>
  <joint name="littleZ_to_wx" type="fixed">
    <origin rpy="0.0 0.0 0.0" xyz="0.0 0.0 0.0"/>
    <parent link="littleZ_link"/>
    <child link="wx_link"/>
  </joint>
</robot>
